Workbook

Sheet KLIENT
A1: PČ | B1: Jméno/Firma | C1: 2026
A2: 1 | B2: Aktiv Novostav s. r. o. | C2: Aktiv Novostav s. r. o.
A3: 2 | B3: BURNING TECHNOLOGY a. s. | C3: BURNING TECHNOLOGY a. s.
A4: 3 | B4: CSE | C4: Delphia MORAVIA s.r.o.
A5: 4 | B5: FSL CZ, s. r. o. | C5: EVUM Motors s.r.o.
A6: 5 | C6: FSL CZ, s. r. o.
A7: 6 | B7: ONE KLIMA, s. r. o. | C7: Maker Inspiration s.r.o.
A8: 7 | B8: VINTECO s. r. o. | C8: XXX
A9: 8 | B9: SUNFRIO | C9: MastrCrane Production, s. r. o.
A10: 9 | B10: výpočet | C10: Michal GNES
A11: 10 | B11: Bezunk Roman | C11: MV Active s.r.o.
A12: 11 | B12: MastrCrane | C12: ONE KLIMA s. r. o.
A13: 12 | B13: Delphia | C13: YYY
A14: 13 | B14: MV ACTIVE | C14: CSE
A15: 14 | C15: výpočet

Sheet ELEKTRO
A1: STAVY | B1: KLIENT | C1: Poznámka | D1: Jedn. | E1: 1. 1. 2026 | F1: 1. 2. 2026 | G1: 1. 3. 2026 | H1: 1. 4. 2026 | I1: 1. 5. 2026 | J1: 1. 6. 2026 | K1: 1. 7. 2026 | L1: 1. 8. 2026 | M1: 1. 9. 2026 | N1: 1. 10. 2026 | O1: 1. 11. 2026 | P1: 1. 12. 2026 | Q1: 1. 1. 2027
A2: E_A1 | B2: ONE KLIMA, s. r. o. | C2: hala A1/A2 | D2: kWh | E2: 20100 | F2: 20250 | G2: 20440 | H2: 20620 | I2: 20770 | J2: 20890 | K2: 21090 | L2: 0 | M2: 0 | N2: 0 | O2: 0 | P2: 0 | Q2: 0
A3: E_AB1 | B3: výpočet | C3: rozpočítáno, admin. budova přízemí | D3: kWh | E3: 20280 | F3: 20500 | G3: 20700 | H3: 20940 | I3: 21140 | J3: 21340 | K3: 21540 | L3: 0 | M3: 0 | N3: 0 | O3: 0 | P3: 0 | Q3: 0
A4: E_AB1_10 | B4: výpočet | C4: spol. 11+12 Kociak/Aktiv, brána, vrátnice | D4: kWh | E4: 1600 | F4: 1640 | G4: 1660 | H4: 1685 | I4: 1710 | J4: 1740 | K4: 1760 | L4: 0 | M4: 0 | N4: 0 | O4: 0 | P4: 0 | Q4: 0
A5: E_AB1_08 | B5: Aktiv Novostav s. r. o. | D5: kWh | E5: 0 | F5: 0 | G5: 0 | H5: 0 | I5: 0 | J5: 0 | K5: 0 | L5: 0 | M5: 0 | N5: 0 | O5: 0 | P5: 0 | Q5: 0
A6: E_AB1_11 | B6: Aktiv Novostav s. r. o. | D6: kWh | E6: 792 | F6: 800 | G6: 805 | H6: 815 | I6: 821 | J6: 830 | K6: 835 | L6: 0 | M6: 0 | N6: 0 | O6: 0 | P6: 0 | Q6: 0
A7: E_AB1_12 | B7: Aktiv Novostav s. r. o. | D7: kWh | E7: 640 | F7: 655 | G7: 670 | H7: 685 | I7: 700 | J7: 715 | K7: 730 | L7: 0 | M7: 0 | N7: 0 | O7: 0 | P7: 0 | Q7: 0
A8: E_AB1_18 | B8: BURNING TECHNOLOGY a. s. | C8: společný prostor WC/Sprchy | D8: kWh | E8: 860 | F8: 865 | G8: 870 | H8: 875 | I8: 875 | J8: 880 | K8: 885 | L8: 0 | M8: 0 | N8: 0 | O8: 0 | P8: 0 | Q8: 0
A9: E_AB1_22 | B9: MV Active s.r.o. | C9: Showroom | D9: kWh | E9: 8860 | F9: 8980 | G9: 9120 | H9: 9240 | I9: 9355 | J9: 9430 | K9: 9500 | L9: 0 | M9: 0 | N9: 0 | O9: 0 | P9: 0 | Q9: 0
A10: E_AB1_23 | B10: MV Active s.r.o. | C10: rack | D10: kWh | E10: 18120 | F10: 18140 | G10: 18175 | H10: 18210 | I10: 18250 | J10: 18280 | K10: 18320 | L10: 0 | M10: 0 | N10: 0 | O10: 0 | P10: 0 | Q10: 0
A11: E_AB1_25 | B11: výpočet | C11: topení, kamery | D11: kWh | E11: 288020 | F11: 288200 | G11: 288370 | H11: 288500 | I11: 288600 | J11: 288640 | K11: 288670 | L11: 0 | M11: 0 | N11: 0 | O11: 0 | P11: 0 | Q11: 0
A12: E_AB1_27 | B12: BURNING TECHNOLOGY a. s. | C12: zkušebna | D12: kWh | E12: 355 | F12: 355 | G12: 355 | H12: 360 | I12: 360 | J12: 360 | K12: 360 | L12: 0 | M12: 0 | N12: 0 | O12: 0 | P12: 0 | Q12: 0
A13: E_AB2 | B13: BURNING TECHNOLOGY a. s. | C13: II. patro + internet | D13: kWh | E13: 31720 | F13: 32120 | G13: 32490 | H13: 32830 | I13: 33130 | J13: 33415 | K13: 33680 | L13: 0 | M13: 0 | N13: 0 | O13: 0 | P13: 0 | Q13: 0
A14: E_AB3 | B14: CSE | C14: 3 NP | D14: kWh | E14: 15120 | F14: 15130 | G14: 15140 | H14: 15155 | I14: 15175 | J14: 15215 | K14: 15250 | L14: 0 | M14: 0 | N14: 0 | O14: 0 | P14: 0 | Q14: 0
A15: E_AB4 | B15: CSE | C15: Příprava kotelna - plyn | D15: kWh | E15: 0 | F15: 0 | G15: 0 | H15: 0 | I15: 0 | J15: 0 | K15: 0 | L15: 0 | M15: 0 | N15: 0 | O15: 0 | P15: 0 | Q15: 0
A16: E_B1 | B16: ONE KLIMA s. r. o. | C16: hala B1/B1A | D16: kWh | E16: 4510 | F16: 4530 | G16: 4540 | H16: 4550 | I16: 4560 | J16: 4570 | K16: 4580 | L16: 0 | M16: 0 | N16: 0 | O16: 0 | P16: 0 | Q16: 0
A17: E_B1A | B17: ONE KLIMA s. r. o. | C17: rack | D17: kWh | E17: 345 | F17: 350 | G17: 350 | H17: 350 | I17: 350 | J17: 350 | K17: 350 | L17: 0 | M17: 0 | N17: 0 | O17: 0 | P17: 0 | Q17: 0
A18: E_B2 | B18: BURNING TECHNOLOGY a. s. | C18: haly B1/B2/C4 | D18: kWh | E18: 114600 | F18: 114650 | G18: 114700 | H18: 114710 | I18: 114710 | J18: 114710 | K18: 114950 | L18: 0 | M18: 0 | N18: 0 | O18: 0 | P18: 0 | Q18: 0
A19: E_C1 | B19: BURNING TECHNOLOGY a. s. | C19: hala C1/C3 | D19: kWh | E19: 3030 | F19: 3050 | G19: 3060 | H19: 3070 | I19: 3075 | J19: 3080 | K19: 3090 | L19: 0 | M19: 0 | N19: 0 | O19: 0 | P19: 0 | Q19: 0
... A34: E_SPOL | B34: výpočet | C34: společná | D34: kWh | E34: 0 | F34: 0 | G34: 0 | H34: 0 | I34: 0 | J34: 0 | K34: 0 | L34: 0 | M34: 0 | N34: 0 | O34: 0 | P34: 0 | Q34: 0
A37: SPOTŘEBY | B37: KLIENT | C37: Poznámka | D37: Koef | E37: ledna | F37: února | G37: března | H37: dubna | I37: května | J37: června | K37: července | L37: srpna | M37: září | N37: října | O37: listopadu | P37: prosince | Q37: Odečet
A38: =$A2 -> E_A1 | B38: =B2 -> ONE KLIMA, s. r. o. | D38: 1 | E38: =$D38*IF(F2=0,0,(F2-E2)) -> 150 | F38: =$D38*IF(G2=0,0,(G2-F2)) -> 190 | G38: =$D38*IF(H2=0,0,(H2-G2)) -> 180 | H38: =$D38*IF(I2=0,0,(I2-H2)) -> 150 | I38: =$D38*IF(J2=0,0,(J2-I2)) -> 120 | J38: =$D38*IF(K2=0,0,(K2-J2)) -> 200 | K38: =$D38*IF(L2=0,0,(L2-K2)) -> 0 | L38: =$D38*IF(M2=0,0,(M2-L2)) -> 0 | ... P38: =$D38*IF(Q2=0,0,(Q2-P2)) -> 0 | Q38: 46204
A39: =$A3 -> E_AB1 | B39: =B3 -> výpočet | D39: 1 | E39: =$D39*IF(F3=0,0,(F3-E3)) -> 220 | F39: =$D39*IF(G3=0,0,(G3-F3)) -> 200 | G39: =$D39*IF(H3=0,0,(H3-G3)) -> 240 | H39: =$D39*IF(I3=0,0,(I3-H3)) -> 200 | I39: =$D39*IF(J3=0,0,(J3-I3)) -> 200 | J39: =$D39*IF(K3=0,0,(K3-J3)) -> 200 | K39: =$D39*IF(L3=0,0,(L3-K3)) -> 0 | L39: =$D39*IF(M3=0,0,(M3-L3)) -> 0 | ... P39: =$D39*IF(Q3=0,0,(Q3-P3)) -> 0 | Q39: =$Q$38 -> 46204
A40: =$A4 -> E_AB1_10 | B40: =B4 -> výpočet | C40: výpočet | D40: 1 | E40: =$D40*IF(F4=0,0,(F4-E4))-E42-E43 -> 17 | F40: =$D40*IF(G4=0,0,(G4-F4))-F42-F43 -> 0 | G40: =$D40*IF(H4=0,0,(H4-G4))-G42-G43 -> 0 | H40: =$D40*IF(I4=0,0,(I4-H4))-H42-H43 -> 4 | I40: =$D40*IF(J4=0,0,(J4-I4))-I42-I43 -> 6 | J40: =$D40*IF(K4=0,0,(K4-J4))-J42-J43 -> 0 | K40: =$D40*IF(L4=0,0,(L4-K4))-K42-K43 -> 0 | L40: =$D40*IF(M4=0,0,(M4-L4))-L42-L43 -> 0 | ... P40: =$D40*IF(Q4=0,0,(Q4-P4))-P42-P43 -> 0 | Q40: =$Q$38 -> 46204
A41: =$A5 -> E_AB1_08 | B41: =B5 -> Aktiv Novostav s. r. o. | D41: 1 | E41: =$D41*IF(F5=0,0,(F5-E5)) -> 0 | F41: =$D41*IF(G5=0,0,(G5-F5)) -> 0 | G41: =$D41*IF(H5=0,0,(H5-G5)) -> 0 | H41: =$D41*IF(I5=0,0,(I5-H5)) -> 0 | I41: =$D41*IF(J5=0,0,(J5-I5)) -> 0 | J41: =$D41*IF(K5=0,0,(K5-J5)) -> 0 | K41: =$D41*IF(L5=0,0,(L5-K5)) -> 0 | L41: =$D41*IF(M5=0,0,(M5-L5)) -> 0 | ... P41: =$D41*IF(Q5=0,0,(Q5-P5)) -> 0 | Q41: =$Q$38 -> 46204
A42: =$A6 -> E_AB1_11 | B42: =B6 -> Aktiv Novostav s. r. o. | D42: 1 | E42: =$D42*IF(F6=0,0,(F6-E6)) -> 8 | F42: =$D42*IF(G6=0,0,(G6-F6)) -> 5 | G42: =$D42*IF(H6=0,0,(H6-G6)) -> 10 | H42: =$D42*IF(I6=0,0,(I6-H6)) -> 6 | I42: =$D42*IF(J6=0,0,(J6-I6)) -> 9 | J42: =$D42*IF(K6=0,0,(K6-J6)) -> 5 | K42: =$D42*IF(L6=0,0,(L6-K6)) -> 0 | L42: =$D42*IF(M6=0,0,(M6-L6)) -> 0 | ... P42: =$D42*IF(Q6=0,0,(Q6-P6)) -> 0 | Q42: =$Q$38 -> 46204
A43: =$A7 -> E_AB1_12 | B43: =B7 -> Aktiv Novostav s. r. o. | D43: 1 | E43: =$D43*IF(F7=0,0,(F7-E7)) -> 15 | F43: =$D43*IF(G7=0,0,(G7-F7)) -> 15 | G43: =$D43*IF(H7=0,0,(H7-G7)) -> 15 | H43: =$D43*IF(I7=0,0,(I7-H7)) -> 15 | I43: =$D43*IF(J7=0,0,(J7-I7)) -> 15 | J43: =$D43*IF(K7=0,0,(K7-J7)) -> 15 | K43: =$D43*IF(L7=0,0,(L7-K7)) -> 0 | L43: =$D43*IF(M7=0,0,(M7-L7)) -> 0 | ... P43: =$D43*IF(Q7=0,0,(Q7-P7)) -> 0 | Q43: =$Q$38 -> 46204
A44: =$A8 -> E_AB1_18 | B44: =B8 -> BURNING TECHNOLOGY a. s. | D44: 1 | E44: =$D44*IF(F8=0,0,(F8-E8)) -> 5 | F44: =$D44*IF(G8=0,0,(G8-F8)) -> 5 | G44: =$D44*IF(H8=0,0,(H8-G8)) -> 5 | H44: =$D44*IF(I8=0,0,(I8-H8)) -> 0 | I44: =$D44*IF(J8=0,0,(J8-I8)) -> 5 | J44: =$D44*IF(K8=0,0,(K8-J8)) -> 5 | K44: =$D44*IF(L8=0,0,(L8-K8)) -> 0 | L44: =$D44*IF(M8=0,0,(M8-L8)) -> 0 | ... P44: =$D44*IF(Q8=0,0,(Q8-P8)) -> 0 | Q44: =$Q$38 -> 46204
A45: =$A9 -> E_AB1_22 | B45: =B9 -> MV Active s.r.o. | D45: 1 | E45: =$D45*IF(F9=0,0,(F9-E9)) -> 120 | F45: =$D45*IF(G9=0,0,(G9-F9)) -> 140 | G45: =$D45*IF(H9=0,0,(H9-G9)) -> 120 | H45: =$D45*IF(I9=0,0,(I9-H9)) -> 115 | I45: =$D45*IF(J9=0,0,(J9-I9)) -> 75 | J45: =$D45*IF(K9=0,0,(K9-J9)) -> 70 | K45: =$D45*IF(L9=0,0,(L9-K9)) -> 0 | L45: =$D45*IF(M9=0,0,(M9-L9)) -> 0 | ... P45: =$D45*IF(Q9=0,0,(Q9-P9)) -> 0 | Q45: =$Q$38 -> 46204
A46: =$A10 -> E_AB1_23 | B46: =B10 -> MV Active s.r.o. | D46: 1 | E46: =$D46*IF(F10=0,0,(F10-E10)) -> 20 | F46: =$D46*IF(G10=0,0,(G10-F10)) -> 35 | G46: =$D46*IF(H10=0,0,(H10-G10)) -> 35 | H46: =$D46*IF(I10=0,0,(I10-H10)) -> 40 | I46: =$D46*IF(J10=0,0,(J10-I10)) -> 30 | J46: =$D46*IF(K10=0,0,(K10-J10)) -> 40 | K46: =$D46*IF(L10=0,0,(L10-K10)) -> 0 | L46: =$D46*IF(M10=0,0,(M10-L10)) -> 0 | ... P46: =$D46*IF(Q10=0,0,(Q10-P10)) -> 0 | Q46: =$Q$38 -> 46204
A47: =$A11 -> E_AB1_25 | B47: =B11 -> výpočet | C47: topení | D47: 1 | E47: =$D47*IF(F11=0,0,(F11-E11)) -> 180 | F47: =$D47*IF(G11=0,0,(G11-F11)) -> 170 | G47: =$D47*IF(H11=0,0,(H11-G11)) -> 130 | H47: =$D47*IF(I11=0,0,(I11-H11)) -> 100 | I47: =$D47*IF(J11=0,0,(J11-I11)) -> 40 | J47: =$D47*IF(K11=0,0,(K11-J11)) -> 30 | K47: =$D47*IF(L11=0,0,(L11-K11)) -> 0 | L47: =$D47*IF(M11=0,0,(M11-L11)) -> 0 | ... P47: =$D47*IF(Q11=0,0,(Q11-P11)) -> 0 | Q47: =$Q$38 -> 46204
A48: =$A12 -> E_AB1_27 | B48: =B12 -> BURNING TECHNOLOGY a. s. | D48: 1 | E48: =$D48*IF(F12=0,0,(F12-E12)) -> 0 | F48: =$D48*IF(G12=0,0,(G12-F12)) -> 0 | G48: =$D48*IF(H12=0,0,(H12-G12)) -> 5 | H48: =$D48*IF(I12=0,0,(I12-H12)) -> 0 | I48: =$D48*IF(J12=0,0,(J12-I12)) -> 0 | J48: =$D48*IF(K12=0,0,(K12-J12)) -> 0 | K48: =$D48*IF(L12=0,0,(L12-K12)) -> 0 | L48: =$D48*IF(M12=0,0,(M12-L12)) -> 0 | ... P48: =$D48*IF(Q12=0,0,(Q12-P12)) -> 0 | Q48: =$Q$38 -> 46204
A49: =$A13 -> E_AB2 | B49: =B13 -> BURNING TECHNOLOGY a. s. | D49: 1 | E49: =$D49*IF(F13=0,0,(F13-E13)) -> 400 | F49: =$D49*IF(G13=0,0,(G13-F13)) -> 370 | G49: =$D49*IF(H13=0,0,(H13-G13)) -> 340 | H49: =$D49*IF(I13=0,0,(I13-H13)) -> 300 | I49: =$D49*IF(J13=0,0,(J13-I13)) -> 285 | J49: =$D49*IF(K13=0,0,(K13-J13)) -> 265 | K49: =$D49*IF(L13=0,0,(L13-K13)) -> 0 | L49: =$D49*IF(M13=0,0,(M13-L13)) -> 0 | ... P49: =$D49*IF(Q13=0,0,(Q13-P13)) -> 0 | Q49: =$Q$38 -> 46204
A50: =$A14 -> E_AB3 | B50: =B14 -> CSE | D50: 1 | E50: =$D50*IF(F14=0,0,(F14-E14)) -> 10 | F50: =$D50*IF(G14=0,0,(G14-F14)) -> 10 | G50: =$D50*IF(H14=0,0,(H14-G14)) -> 15 | H50: =$D50*IF(I14=0,0,(I14-H14)) -> 20 | I50: =$D50*IF(J14=0,0,(J14-I14)) -> 40 | J50: =$D50*IF(K14=0,0,(K14-J14)) -> 35 | K50: =$D50*IF(L14=0,0,(L14-K14)) -> 0 | L50: =$D50*IF(M14=0,0,(M14-L14)) -> 0 | ... P50: =$D50*IF(Q14=0,0,(Q14-P14)) -> 0 | Q50: =$Q$38 -> 46204
A51: =$A15 -> E_AB4 | B51: =B15 -> CSE | D51: 1 | E51: =$D51*IF(F15=0,0,(F15-E15)) -> 0 | F51: =$D51*IF(G15=0,0,(G15-F15)) -> 0 | G51: =$D51*IF(H15=0,0,(H15-G15)) -> 0 | H51: =$D51*IF(I15=0,0,(I15-H15)) -> 0 | I51: =$D51*IF(J15=0,0,(J15-I15)) -> 0 | J51: =$D51*IF(K15=0,0,(K15-J15)) -> 0 | K51: =$D51*IF(L15=0,0,(L15-K15)) -> 0 | L51: =$D51*IF(M15=0,0,(M15-L15)) -> 0 | ... P51: =$D51*IF(Q15=0,0,(Q15-P15)) -> 0 | Q51: =$Q$38 -> 46204
A52: =$A16 -> E_B1 | B52: =B16 -> ONE KLIMA s. r. o. | D52: 1 | E52: =$D52*IF(F16=0,0,(F16-E16)) -> 20 | F52: =$D52*IF(G16=0,0,(G16-F16)) -> 10 | G52: =$D52*IF(H16=0,0,(H16-G16)) -> 10 | H52: =$D52*IF(I16=0,0,(I16-H16)) -> 10 | I52: =$D52*IF(J16=0,0,(J16-I16))-I65 -> 10 | J52: =$D52*IF(K16=0,0,(K16-J16)) -> 10 | K52: =$D52*IF(L16=0,0,(L16-K16)) -> 0 | L52: =$D52*IF(M16=0,0,(M16-L16)) -> 0 | M52: =$D52*IF(N16=0,0,(N16-M16)) -> 0 | N52: =$D52*IF(O16=0,0,(O16-N16)) -> 0 | O52: =$D52*IF(P16=0,0,(P16-O16)) -> 0 | P52: =$D52*IF(Q16=0,0,(Q16-P16)) -> 0 | Q52: =$Q$38 -> 46204
A53: =$A17 -> E_B1A | B53: =$B17 -> ONE KLIMA s. r. o. | C53: rack | D53: 1 | E53: =$D53*IF(F17=0,0,(F17-E17)) -> 5 | F53: =$D53*IF(G17=0,0,(G17-F17)) -> 0 | G53: =$D53*IF(H17=0,0,(H17-G17)) -> 0 | H53: =$D53*IF(I17=0,0,(I17-H17)) -> 0 | I53: =$D53*IF(J17=0,0,(J17-I17)) -> 0 | J53: =$D53*IF(K17=0,0,(K17-J17)) -> 0 | K53: =$D53*IF(L17=0,0,(L17-K17)) -> 0 | L53: =$D53*IF(M17=0,0,(M17-L17)) -> 0 | ... P53: =$D53*IF(Q17=0,0,(Q17-P17)) -> 0 | Q53: =$Q$38 -> 46204
A54: =$A18 -> E_B2 | B54: =B18 -> BURNING TECHNOLOGY a. s. | C54: výpočet, podružné B1/B1A/B1Z/B2Z | D54: 1 | E54: =$D54*IF(F18=0,0,(F18-E18))-E52-E53-E65-E66 -> 25 | F54: =$D54*IF(G18=0,0,(G18-F18))-F52-F53-F65-F66 -> 40 | G54: =$D54*IF(H18=0,0,(H18-G18))-G52-G53-G65-G66 -> 0 | H54: =$D54*IF(I18=0,0,(I18-H18)) -> 0 | I54: =$D54*IF(J18=0,0,(J18-I18))-I66 -> 0 | J54: =$D54*IF(K18=0,0,(K18-J18)) -> 240 | K54: =$D54*IF(L18=0,0,(L18-K18)) -> 0 | L54: =$D54*IF(M18=0,0,(M18-L18)) -> 0 | M54: =$D54*IF(N18=0,0,(N18-M18)) -> 0 | N54: =$D54*IF(O18=0,0,(O18-N18)) -> 0 | O54: =$D54*IF(P18=0,0,(P18-O18)) -> 0 | P54: =$D54*IF(Q18=0,0,(Q18-P18)) -> 0 | Q54: =$Q$38 -> 46204
A55: =$A19 -> E_C1 | B55: =B19 -> BURNING TECHNOLOGY a. s. | D55: 1 | E55: =$D55*IF(F19=0,0,(F19-E19)) -> 20 | F55: =$D55*IF(G19=0,0,(G19-F19)) -> 10 | G55: =$D55*IF(H19=0,0,(H19-G19)) -> 10 | H55: =$D55*IF(I19=0,0,(I19-H19)) -> 5 | I55: =$D55*IF(J19=0,0,(J19-I19)) -> 5 | J55: =$D55*IF(K19=0,0,(K19-J19)) -> 10 | K55: =$D55*IF(L19=0,0,(L19-K19)) -> 0 | L55: =$D55*IF(M19=0,0,(M19-L19)) -> 0 | ... P55: =$D55*IF(Q19=0,0,(Q19-P19)) -> 0 | Q55: =$Q$38 -> 46204
A56: =$A20 -> E_C2 | B56: =B20 -> FSL CZ, s. r. o. | D56: 1 | E56: =$D56*IF(F20=0,0,(F20-E20)) -> 480 | F56: =$D56*IF(G20=0,0,(G20-F20)) -> 440 | G56: =$D56*IF(H20=0,0,(H20-G20)) -> 315 | H56: =$D56*IF(I20=0,0,(I20-H20)) -> 385 | I56: =$D56*IF(J20=0,0,(J20-I20)) -> 135 | J56: =$D56*IF(K20=0,0,(K20-J20)) -> 155 | K56: =$D56*IF(L20=0,0,(L20-K20)) -> 0 | L56: =$D56*IF(M20=0,0,(M20-L20)) -> 0 | ... P56: =$D56*IF(Q20=0,0,(Q20-P20)) -> 0 | Q56: =$Q$38 -> 46204
...

Sheet VODA
A1: STAVY | B1: KLIENT | C1: Poznámka | D1: Jedn. | E1: =ELEKTRO!E1 -> 1. 1. 2026 | F1: =ELEKTRO!F1 -> 1. 2. 2026 | G1: =ELEKTRO!G1 -> 1. 3. 2026 | H1: =ELEKTRO!H1 -> 1. 4. 2026 | I1: =ELEKTRO!I1 -> 1. 5. 2026 | J1: =ELEKTRO!J1 -> 1. 6. 2026 | K1: =ELEKTRO!K1 -> 1. 7. 2026 | L1: =ELEKTRO!L1 -> 1. 8. 2026 | ... Q1: =ELEKTRO!Q1 -> 1. 1. 2027
A2: W_CELKEM | B2: výpočet | D2: m3 | E2: 524 | F2: 530 | G2: 535 | H2: 541 | I2: 547 | J2: 553 | K2: 561 | L2: 0 | M2: 0 | N2: 0 | O2: 0 | P2: 0 | Q2: 0
A5: SPOTŘEBY | B5: KLIENT | C5: Poznámka | D5: Koef | E5: 44562 | F5: 44593 | G5: 44621 | H5: 44652 | I5: 44682 | J5: 44713 | K5: 44743 | L5: 44774 | M5: 44805 | N5: 44835 | O5: 44866 | P5: 44896
A6: =$A2 -> W_CELKEM | B6: =B2 -> výpočet | D6: 1 | E6: =$D6*IF(F2=0,0,(F2-E2)) -> 6 | F6: =$D6*IF(G2=0,0,(G2-F2)) -> 5 | G6: =$D6*IF(H2=0,0,(H2-G2)) -> 6 | H6: =$D6*IF(I2=0,0,(I2-H2)) -> 6 | I6: =$D6*IF(J2=0,0,(J2-I2)) -> 6 | J6: =$D6*IF(K2=0,0,(K2-J2)) -> 8 | K6: =$D6*IF(L2=0,0,(L2-K2)) -> 0 | L6: =$D6*IF(M2=0,0,(M2-L2)) -> 0 | ... P6: =$D6*IF(Q2=0,0,(Q2-P2)) -> 0
A8: CELKEM: | E8: =SUM(E6) -> 6 | F8: =SUM(F6) -> 5 | G8: =SUM(G6) -> 6 | H8: =SUM(H6) -> 6 | I8: 6 | J8: =SUM(J6) -> 8 | K8: =SUM(K6) -> 0 | L8: =SUM(L6) -> 0 | M8: =SUM(M6) -> 0 | N8: =SUM(N6) -> 0 | O8: =SUM(O6) -> 0 | P8: =SUM(P6) -> 0
A10: Celkem odečtena spotřeba m3 | E10: =E8 -> 6 | F10: =F8 -> 5 | G10: =G8 -> 6 | H10: =H8 -> 6 | I10: =I8 -> 6 | J10: =J8 -> 8 | K10: 0 | L10: =L8 -> 0 | M10: =M8 -> 0 | N10: =N8 -> 0 | O10: =O8 -> 0 | P10: =P8 -> 0
A11: Fakturovaná spotřeba m3 | E11: 6 | F11: 0 | G11: 0 | H11: 0 | I11: 0 | J11: 0 | K11: 0 | L11: 0 | M11: 0 | N11: 0 | O11: 0 | P11: 0
A12: Rozdíl (chybí/přebývá) kWh | E12: =E10-E11 -> 0 | F12: =F10-F11 -> 5 | G12: =G10-G11 -> 6 | H12: =H10-H11 -> 6 | I12: =I10-I11 -> 6 | J12: =J10-J11 -> 8 | K12: =K10-K11 -> 0 | L12: =L10-L11 -> 0 | ... P12: =P10-P11 -> 0
A13: Rozdíl (chybí/přebývá) % | E13: =IF(E10>0,E12/E10,0) -> 0 | F13: =IF(F10>0,F12/F10,0) -> 1 | G13: =IF(G10>0,G12/G10,0) -> 1 | H13: =IF(H10>0,H12/H10,0) -> 1 | I13: =IF(I10>0,I12/I10,0) -> 1 | J13: =IF(J10>0,J12/J10,0) -> 1 | K13: =IF(K10>0,K12/K10,0) -> 0 | L13: =IF(L10>0,L12/L10,0) -> 0 | ... P13: =IF(P10>0,P12/P10,0) -> 0
A14: Fakturace celkem Kč | C14: sazba 128,63 Kč/m3 | E14: =E11*128.63 -> 771.78 | F14: 0 | G14: 0 | H14: 0 | I14: 0 | J14: 0 | K14: 0 | L14: 0 | M14: 0 | N14: 0 | O14: 0 | P14: 0

Sheet TEPLO
A1: STAVY | B1: KLIENT | C1: Poznámka | D1: Jedn. | E1: =ELEKTRO!E1 -> 1. 1. 2026 | F1: =ELEKTRO!F1 -> 1. 2. 2026 | G1: =ELEKTRO!G1 -> 1. 3. 2026 | H1: =ELEKTRO!H1 -> 1. 4. 2026 | I1: =ELEKTRO!I1 -> 1. 5. 2026 | J1: =ELEKTRO!J1 -> 1. 6. 2026 | K1: =ELEKTRO!K1 -> 1. 7. 2026 | L1: =ELEKTRO!L1 -> 1. 8. 2026 | ... Q1: =ELEKTRO!Q1 -> 1. 1. 2027
A2: T_CELKEM | B2: výpočet | C2: rozúčtováno dle m2 | D2: kWh | E2: 288020 | F2: 288200 | G2: 288370 | H2: 288480 | I2: 288600 | J2: 288640 | K2: 288670 | L2: 0 | M2: 0 | N2: 0 | O2: 0 | P2: 0 | Q2: 0
A3: T_PELETY | C3: spotřeba pelet | D3: kg | E3: 0 | F3: 3150 | G3: 3150 | H3: 1950 | I3: 1000 | J3: 400 | K3: 0 | L3: 0 | M3: 0 | N3: 0 | O3: 0 | P3: 0 | Q3: 0
B4: ß
A6: SPOTŘEBY | B6: KLIENT | C6: Poznámka | D6: Koef | E6: 44562 | F6: 44593 | G6: 44621 | H6: 44652 | I6: 44682 | J6: 44713 | K6: 44743 | L6: 44774 | M6: 44805 | N6: 44835 | O6: 44866 | P6: 44896
A7: =$A2 -> T_CELKEM | B7: =B2 -> výpočet | D7: 1 | E7: =$D7*IF(F2=0,0,(F2-E2)) -> 180 | F7: =$D7*IF(G2=0,0,(G2-F2)) -> 170 | G7: 110 | H7: 110 | I7: 120 | J7: 0 | K7: 0 | L7: 0 | M7: 0 | N7: 0 | O7: 0 | P7: 0
A8: =A3 -> T_PELETY | D8: 1 | E8: =F3 -> 3150 | F8: =G3 -> 3150 | G8: =H3 -> 1950 | H8: =I3 -> 1000 | I8: =J3 -> 400 | J8: =K3 -> 0 | K8: =L3 -> 0 | L8: =M3 -> 0 | ... P8: =Q3 -> 0
A9: CELKEM: | E9: =SUM(E7) -> 180 | F9: =SUM(F7) -> 170 | G9: =SUM(G7) -> 110 | H9: =SUM(H7) -> 110 | I9: =SUM(I7) -> 120 | J9: =SUM(J7) -> 0 | K9: =SUM(K7) -> 0 | L9: =SUM(L7) -> 0 | ... P9: =SUM(P7) -> 0
A11: Celkem odečtena spotřeba kWh | E11: =E9 -> 180 | F11: =F9 -> 170 | G11: =G9 -> 110 | H11: =H9 -> 110 | I11: =I9 -> 120 | J11: =J9 -> 0 | K11: =K9 -> 0 | L11: =L9 -> 0 | ... P11: =P9 -> 0
A12: Fakturovaná spotřeba kWh | E12: =E11*1.04 -> 187.2 | F12: =F11*1.04 -> 176.8 | G12: =G11*1.04 -> 114.4 | H12: =H11*1.04 -> 114.4 | I12: =I11*1.04 -> 124.8 | J12: =J11*1.04 -> 0 | K12: =K11*1.04 -> 0 | L12: =L11*1.04 -> 0 | ... P12: =P11*1.04 -> 0
A13: cena Kč/kWh | E13: =ELEKTRO!E80 -> 7.138523 | F13: =ELEKTRO!F80 -> 6.7988669 | G13: =ELEKTRO!G80 -> 7.1547497 | H13: =ELEKTRO!H80 -> 5.942608 | I13: =ELEKTRO!I80 -> 6.1710414 | J13: =ELEKTRO!J80 -> 6.2299942 | K13: =ELEKTRO!K80 -> 0 | L13: =ELEKTRO!L80 -> 0 | ... P13: =ELEKTRO!P80 -> 0
A14: cena pelet Kč/kg | E14: 10.89 | F14: 10.89 | G14: 10.89 | H14: 10.89 | I14: 10.89
A15: Kč pelety | E15: =E8*E14 -> 34303.5 | F15: =F8*F14 -> 34303.5 | G15: =G8*G14 -> 21235.5 | H15: =H8*H14 -> 10890 | I15: =I8*I14 -> 4356 | J15: =J8*J14 -> 0 | K15: =K8*K14 -> 0 | L15: =L8*L14 -> 0 | ... P15: =P8*P14 -> 0
A16: Celkem Kč | E16: =(E12*ELEKTRO!E80)+E15 -> 35639.832 | F16: =(F12*ELEKTRO!F80)+F15 -> 35505.54 | G16: =(G12*ELEKTRO!G80)+G15 -> 22054.003 | H16: =(H12*ELEKTRO!H80)+H15 -> 11569.834 | I16: =(I12*ELEKTRO!I80)+I15 -> 5126.146 | J16: =(J12*ELEKTRO!J80)+J15 -> 0 | K16: =(K12*ELEKTRO!K80)+K15 -> 0 | L16: =(L12*ELEKTRO!L80)+L15 -> 0 | ... P16: =(P12*ELEKTRO!P80)+P15 -> 0

Sheet RADIATORY
A1: Tabulka 1
B2: Radiátory | C2: kwh | D2: Kč/kwh | E2: Kč el. | F2: kg | G2: Kč/kg | H2: Kč pelety | I2: Kč celkem
A3: CELKEM | B3: 26 | C3: 0 | D3: 0 | E3: =C3*D3 -> 0 | F3: 400 | G3: 10.89 | H3: =F3*G3 -> 4356 | I3: =H3+E3 -> 4356
A5: SPOLECNE PROSTORY | B5: 10 | C5: =$B5/$B3*C3 -> 0 | E5: =C5*$D$3 -> 0 | F5: =$B5/$B3*F3 -> 153.84615 | H5: =F5*$G$3 -> 1675.3846 | I5: =H5+E5 -> 1675.3846
A6: VYTAPENE KANC.+SKLADY | B6: 16 | C6: =$B6/$B3*C3 -> 0 | E6: =C6*$D$3 -> 0 | F6: =$B6/$B3*F3 -> 246.15385 | H6: =F6*$G$3 -> 2680.6154 | I6: =H6+E6 -> 2680.6154
